<?xml version="1.0" ?>
<!-- =================================================================================== -->
<!-- |    This document was autogenerated by xacro from urdf/car_init.xacro            | -->
<!-- |    EDITING THIS FILE BY HAND IS NOT RECOMMENDED                                 | -->
<!-- =================================================================================== -->
<robot xmlns:xacro="http://www.ros.org/wiki/xacro" name="car_init">
  <material name="silver">
    <color rgba="0.700 0.700 0.700 1.000"/>
  </material>
  <transmission name="Revolute 1_tran">
    <type>transmission_interface/SimpleTransmission</type>
    <joint name="Revolute 1">
      <hardwareInterface>hardware_interface/EffortJointInterface</hardwareInterface>
    </joint>
    <actuator name="Revolute 1_actr">
      <hardwareInterface>hardware_interface/EffortJointInterface</hardwareInterface>
      <mechanicalReduction>1</mechanicalReduction>
    </actuator>
  </transmission>
  <transmission name="Revolute 2_tran">
    <type>transmission_interface/SimpleTransmission</type>
    <joint name="Revolute 2">
      <hardwareInterface>hardware_interface/EffortJointInterface</hardwareInterface>
    </joint>
    <actuator name="Revolute 2_actr">
      <hardwareInterface>hardware_interface/EffortJointInterface</hardwareInterface>
      <mechanicalReduction>1</mechanicalReduction>
    </actuator>
  </transmission>
  <transmission name="Revolute 3_tran">
    <type>transmission_interface/SimpleTransmission</type>
    <joint name="Revolute 3">
      <hardwareInterface>hardware_interface/EffortJointInterface</hardwareInterface>
    </joint>
    <actuator name="Revolute 3_actr">
      <hardwareInterface>hardware_interface/EffortJointInterface</hardwareInterface>
      <mechanicalReduction>1</mechanicalReduction>
    </actuator>
  </transmission>
  <transmission name="Revolute 4_tran">
    <type>transmission_interface/SimpleTransmission</type>
    <joint name="Revolute 4">
      <hardwareInterface>hardware_interface/EffortJointInterface</hardwareInterface>
    </joint>
    <actuator name="Revolute 4_actr">
      <hardwareInterface>hardware_interface/EffortJointInterface</hardwareInterface>
      <mechanicalReduction>1</mechanicalReduction>
    </actuator>
  </transmission>
  <gazebo>
    <plugin name="control" filename="libgazebo_ros_control.so"/>
  </gazebo>
  <gazebo reference="base_link">
    <material>Gazebo/Silver</material>
    <mu1>0.2</mu1>
    <mu2>0.2</mu2>
    <selfCollide>true</selfCollide>
    <gravity>true</gravity>
  </gazebo>
  <gazebo reference="back_left_1">
    <material>Gazebo/Silver</material>
    <mu1>0.2</mu1>
    <mu2>0.2</mu2>
    <selfCollide>true</selfCollide>
  </gazebo>
  <gazebo reference="front_left_1">
    <material>Gazebo/Silver</material>
    <mu1>0.2</mu1>
    <mu2>0.2</mu2>
    <selfCollide>true</selfCollide>
  </gazebo>
  <gazebo reference="back_right_1">
    <material>Gazebo/Silver</material>
    <mu1>0.2</mu1>
    <mu2>0.2</mu2>
    <selfCollide>true</selfCollide>
  </gazebo>
  <gazebo reference="front_right_1">
    <material>Gazebo/Silver</material>
    <mu1>0.2</mu1>
    <mu2>0.2</mu2>
    <selfCollide>true</selfCollide>
  </gazebo>
  <link name="base_link">
    <inertial>
      <origin xyz="3.2004209190434824e-07 0.0 0.025000000000000005" rpy="0 0 0"/>
      <mass value="15.897292018645437"/>
      <inertia ixx="0.058003" iyy="0.056592" izz="0.108043" ixy="-0.0" iyz="0.0" ixz="0.0"/>
    </inertial>
    <visual>
      <origin xyz="0 0 0" rpy="0 0 0"/>
      <geometry>
        <mesh filename="package://car_init_description/meshes/base_link.stl" scale="0.001 0.001 0.001"/>
      </geometry>
      <material name="silver"/>
    </visual>
    <collision>
      <origin xyz="0 0 0" rpy="0 0 0"/>
      <geometry>
        <mesh filename="package://car_init_description/meshes/base_link.stl" scale="0.001 0.001 0.001"/>
      </geometry>
    </collision>
  </link>
  <link name="back_left_1">
    <inertial>
      <origin xyz="-3.505043161822208e-07 -0.010000000000000009 -6.938893903907228e-18" rpy="0 0 0"/>
      <mass value="0.09349379737083224"/>
      <inertia ixx="4.1e-05" iyy="7.5e-05" izz="4.1e-05" ixy="-0.0" iyz="-0.0" ixz="-0.0"/>
    </inertial>
    <visual>
      <origin xyz="-0.070432 0.12 -0.025" rpy="0 0 0"/>
      <geometry>
        <mesh filename="package://car_init_description/meshes/back_left_1.stl" scale="0.001 0.001 0.001"/>
      </geometry>
      <material name="silver"/>
    </visual>
    <collision>
      <origin xyz="-0.070432 0.12 -0.025" rpy="0 0 0"/>
      <geometry>
        <mesh filename="package://car_init_description/meshes/back_left_1.stl" scale="0.001 0.001 0.001"/>
      </geometry>
    </collision>
  </link>
  <link name="front_left_1">
    <inertial>
      <origin xyz="-7.313057835689474e-08 -0.010000000000000009 -6.938893903907228e-18" rpy="0 0 0"/>
      <mass value="0.09349379737083224"/>
      <inertia ixx="4.1e-05" iyy="7.5e-05" izz="4.1e-05" ixy="-0.0" iyz="-0.0" ixz="-0.0"/>
    </inertial>
    <visual>
      <origin xyz="0.07038 0.12 -0.025" rpy="0 0 0"/>
      <geometry>
        <mesh filename="package://car_init_description/meshes/front_left_1.stl" scale="0.001 0.001 0.001"/>
      </geometry>
      <material name="silver"/>
    </visual>
    <collision>
      <origin xyz="0.07038 0.12 -0.025" rpy="0 0 0"/>
      <geometry>
        <mesh filename="package://car_init_description/meshes/front_left_1.stl" scale="0.001 0.001 0.001"/>
      </geometry>
    </collision>
  </link>
  <link name="back_right_1">
    <inertial>
      <origin xyz="-3.505043161822208e-07 0.010000000000000009 -6.938893903907228e-18" rpy="0 0 0"/>
      <mass value="0.09349379737083224"/>
      <inertia ixx="4.1e-05" iyy="7.5e-05" izz="4.1e-05" ixy="-0.0" iyz="0.0" ixz="-0.0"/>
    </inertial>
    <visual>
      <origin xyz="-0.070432 -0.12 -0.025" rpy="0 0 0"/>
      <geometry>
        <mesh filename="package://car_init_description/meshes/back_right_1.stl" scale="0.001 0.001 0.001"/>
      </geometry>
      <material name="silver"/>
    </visual>
    <collision>
      <origin xyz="-0.070432 -0.12 -0.025" rpy="0 0 0"/>
      <geometry>
        <mesh filename="package://car_init_description/meshes/back_right_1.stl" scale="0.001 0.001 0.001"/>
      </geometry>
    </collision>
  </link>
  <link name="front_right_1">
    <inertial>
      <origin xyz="-7.313057835689474e-08 0.010000000000000009 -6.938893903907228e-18" rpy="0 0 0"/>
      <mass value="0.09349379737083224"/>
      <inertia ixx="4.1e-05" iyy="7.5e-05" izz="4.1e-05" ixy="0.0" iyz="0.0" ixz="-0.0"/>
    </inertial>
    <visual>
      <origin xyz="0.07038 -0.12 -0.025" rpy="0 0 0"/>
      <geometry>
        <mesh filename="package://car_init_description/meshes/front_right_1.stl" scale="0.001 0.001 0.001"/>
      </geometry>
      <material name="silver"/>
    </visual>
    <collision>
      <origin xyz="0.07038 -0.12 -0.025" rpy="0 0 0"/>
      <geometry>
        <mesh filename="package://car_init_description/meshes/front_right_1.stl" scale="0.001 0.001 0.001"/>
      </geometry>
    </collision>
  </link>
  <joint name="Revolute 1" type="continuous">
    <origin xyz="0.070432 -0.12 0.025" rpy="0 0 0"/>
    <parent link="base_link"/>
    <child link="back_left_1"/>
    <axis xyz="0.0 -1.0 0.0"/>
  </joint>
  <joint name="Revolute 2" type="continuous">
    <origin xyz="-0.07038 -0.12 0.025" rpy="0 0 0"/>
    <parent link="base_link"/>
    <child link="front_left_1"/>
    <axis xyz="0.0 -1.0 0.0"/>
  </joint>
  <joint name="Revolute 3" type="continuous">
    <origin xyz="0.070432 0.12 0.025" rpy="0 0 0"/>
    <parent link="base_link"/>
    <child link="back_right_1"/>
    <axis xyz="0.0 -1.0 0.0"/>
  </joint>
  <joint name="Revolute 4" type="continuous">
    <origin xyz="-0.07038 0.12 0.025" rpy="0 0 0"/>
    <parent link="base_link"/>
    <child link="front_right_1"/>
    <axis xyz="0.0 -1.0 0.0"/>
  </joint>
</robot>
